Workbook

Sheet Academic Signing Day
A1: ACADEMIC SIGNING DAY | B1: 2025 | S1: ACADEMIC SIGNING DAY | T1: 2024
A2: Total Sponsorship Amount Sold | B2: =SUM(D9:D27) -> 17500 | K2: OUTSTANDING | S2: Total Sponsorship Amount Sold | T2: =SUM(U9:U17) -> 15000
A3: Budget Goal | B3: 10000 | K3: =MIN(K23-B2) -> -1000 | S3: Budget Goal | T3: 9000
A4: Remaining Balance | B4: =MIN(B2-B3) -> 7500 | K4: =K23/B2 -> 0.94285714 | S4: Remaining Balance | T4: =MIN(T2-T3) -> 6000
A5: Stretch Goal | B5: 20000 | S5: Stretch Goal | T5: 11000
A6: Remaining Balance | B6: =MIN(B2-B5) -> -2500 | S6: Remaining Balance | T6: =MIN(T2-T5) -> 4000
A8: SPONSOR NAME | B8: SPONSORSHIP | C8: COST | D8: PRICE PLEDGED | E8: SOLD BY | F8: DATE SOLD | G8: NOTES | H8: SPECIAL BILLING | I8: INVOICED | J8: DATE PAID | K8: PAID AMOUNT | L8: CONTACT | M8: PHONE | N8: EMAIL | P8: SOLD BY | Q8: PLEDGED | S8: SPONSOR NAME | T8: SPONSORSHIP | U8: PRICE PLEDGED | V8: SOLD BY
A9: State Farm Jay Bernard | B9: Title | C9: 5000 | D9: 5000 | E9: BL | F9: 2.28.25 | G9: Will provide a $1000 scholarship | H9: YES | J9: 3.19.25 | K9: 5000 | L9: Jay Bernard | N9: jay.bernard.l8if@statefarm.com | P9: BL | Q9: 13500 | S9: Acxiom | T9: Presenting | U9: 3500 | V9: BL
A10: Acxiom | B10: Presenting | C10: 3500 | D10: 3500 | E10: BL | F10: 1.8.25 | J10: 5.1.25 | K10: 3500 | L10: Crystal Floyd, Alison Cowles | N10: Crystal.Floyd@acxiom.com; Alison.Cowles@acxiom.com | P10: BL-N | Q10: 4000 | S10: Conway Corporation | T10: Gold | U10: 1500 | V10: BL
A11: Turbare | B11: Awards | C11: 2500 | D11: 2500 | E11: BL-N | F11: 1.3.25 | G11: Turbare rep. will participate in awards presentation but no speaking role. | H11: YES | J11: 7.7.25 | K11: 2500 | L11: Laura Martin, Andria White | N11: ceo@turbare.org; awhite@turbare.org | P11: BL-O | S11: Conway Regional | T11: Gold | U11: 500 | V11: BL
B12: Media | C12: 2500 | P12: CP | S12: Crafton Tull | T12: Gold | U12: 1000 | V12: BL
A13: Virco | B13: Gold | C13: 1000 | D13: 1000 | E13: BL | F13: 12.2.24 | H13: YES | J13: 45902 | K13: 1000 | L13: Scotty Bell, Steve Presley | N13: scottybell@virco.com; stevepresley@virco.com | P13: CP-N | S13: Green Bay Packaging | T13: Gold | U13: 1000 | V13: BL
A14: Green Bay Packaging | B14: Gold | C14: 1000 | D14: 1000 | E14: BL | F14: 12.3.24 | H14: YES | J14: 6.5.25 | K14: 1000 | L14: Brad Harville, Christy Prater | N14: bharville@gbp.com, cprater@gbp.com | P14: CP-O | S14: Klaasmeyer | T14: Gold | U14: 1000 | V14: BL
A15: Conway Regional | B15: Gold | C15: 1000 | D15: 500 | E15: BL | F15: 12.30.24 | J15: 4.9.25 | K15: 500 | L15: Rebekah Fincher | N15: rfincher@conwayregional.org | P15: JE | S15: Smith Ford | T15: Gold | U15: 500 | V15: BL
A16: TriTechne | B16: Gold | C16: 1000 | D16: 1500 | E16: BL-N | F16: 1.9.25 | G16: Please send all invoices to ap@tritechne.com and Kara.Turner@tritechne.com | J16: 5.12.25 | K16: 1500 | L16: Lauren Blackwell | N16: lauren.blackwell@tritechne.com | P16: JE-N | S16: State Farm, Jay Bernard | T16: Title | U16: 5000 | V16: BL-N
A17: Crafton Tull | B17: Gold | C17: 1000 | D17: 1000 | E17: BL | F17: 1.10.25 | H17: YES | J17: 45887 | K17: 1000 | L17: Lane Housley | N17: lane.housley@craftontull.com | P17: JE-O | S17: Virco | T17: Gold | U17: 1000 | V17: BL
A18: Smith Ford | B18: Gold | C18: 1000 | D18: 500 | E18: BL | F18: 2.1.25 | J18: 4.7.25 | K18: 500 | L18: Cate McConnell | N18: cate.mcconnell@smithford.com | P18: JG
A19: Klaasmeyer | B19: Gold | C19: 1000 | D19: 1000 | E19: BL | F19: 3.4.25 | G19: Use money being held in BP account. | H19: YES | P19: JG-N
P20: JG-O
P21: LC
P22: LC-N
K23: =SUM(K9:K22) -> 16500 | P23: LC-O
P24: LH
P25: LH-N
P26: LH-O
P27: (blank)
P28: TOTAL | Q28: 17500
E300: BL-O
E301: BL-N
E302: BL
E303: CP-O
E304: CP-N
E305: CP
E306: JG-O
E307: JG-N
E308: JG
E309: JE-O
E310: JE-N
E311: JE
... E317: LH

Sheet Annual Meeting
A1: ANNUAL MEETING | B1: 2025 | S1: ANNUAL MEETING | T1: 2024
A2: Total Sponsorship Amount Sold | B2: =SUM(D9:D117) -> 293000 | G2: WAITLIST: | K2: OUTSTANDING | S2: Total Sponsorship Amount Sold | T2: =SUM(U9:U100) -> 305120
A3: Budget Goal | B3: 255000 | K3: =MIN(K120-B2) -> -22064.5 | S3: Budget Goal | T3: 215000
A4: Remaining Balance | B4: =MIN(B2-B3) -> 38000 | K4: =K120/B2 -> 0.92469454 | S4: Remaining Balance | T4: =MIN(T2-T3) -> 90120
A5: Stretch Goal | B5: 305000 | S5: Stretch Goal | T5: 300000
A6: Remaining Balance | B6: =MIN(B2-B5) -> -12000 | S6: Remaining Balance | T6: =MIN(T2-T5) -> 5120
A8: SPONSOR NAME | B8: SPONSORSHIP | C8: COST | D8: PRICE PLEDGED | E8: SOLD BY | F8: DATE SOLD | G8: NOTES | H8: SPECIAL BILLING | I8: INVOICED | J8: DATE PAID | K8: PAID AMOUNT | L8: CONTACT | M8: PHONE | N8: EMAIL | P8: SOLD BY | Q8: PLEDGED | S8: SPONSOR NAME | T8: SPONSORSHIP | U8: PRICE PLEDGED | V8: SOLD BY
A9: EOS Drew Spurgers | B9: Title | C9: 25000 | D9: 20000 | E9: LH-N | F9: 1.28.25 | G9: Drew wants to talk + do a video | H9: YES | J9: 45954 | K9: 8925 | L9: Drew Spurgers | N9: drew.spurgers@eosworldwide.com | P9: BL | Q9: 133000 | S9: Acxiom | T9: Presenting | U9: 15000 | V9: BL
A10: Acxiom | B10: Presenting | C10: 15000 | D10: 15000 | E10: BL | F10: 1.8.25 | J10: 3.13.25 | K10: 15000 | L10: Crystal Floyd, Alison Cowles | N10: Crystal.Floyd@acxiom.com; Alison.Cowles@acxiom.com | P10: BL-N | Q10: 12350 | S10: American Safeguard Insurance | T10: Silver | U10: 1500 | V10: LH
A11: First Security Bank/Crews & Associates | B11: Presenting | C11: 15000 | D11: 15000 | E11: BL | F11: 2.12.25 | J11: 2.26.25, 3.14.25 | K11: 7500 | L11: Jon Ross Henderson, Stefanie Vann | P11: BL-O | S11: ARcare | T11: Silver | U11: 1500 | V11: LH-N
B12: Presenting | C12: 15000 | J12: 3.14.25 | K12: 7500 | P12: CP | S12: Arkansas Business Publishing Group | T12: Silver | U12: 1500 | V12: BL
A13: UCA | B13: Underwriter | C13: 10000 | D13: 7000 | E13: LH-O | F13: 12.11.24 | G13: Plus $3,000 in-kind fo facility rental. | J13: 4.30.25 | K13: 7000 | L13: Amy Whitehead, Mary Lackie | N13: amyw@uca.edu; mlackie@uca.edu | P13: CP-N | Q13: 10850 | S13: Arkansas Roofing Kompany | T13: Gold | U13: 2850 | V13: LC
A14: Conway Regional | B14: Underwriter | C14: 10000 | D14: 10000 | E14: BL | F14: 12.30.24 | J14: 5.22.25 | K14: 10000 | L14: Rebekah Fincher | N14: rfincher@conwayregional.org | P14: CP-O | S14: Arvest | T14: Gold | U14: 2850 | V14: BL
A15: Turbare | B15: Underwriter | C15: 10000 | D15: 10000 | E15: BL | F15: 1.3.25 | G15: Turbare rep. speaks at event, 3 tables | H15: YES | J15: 4.15.25 | K15: 10000 | L15: Laura Martin, Andria White | N15: ceo@turbare.org; awhite@turbare.org | P15: JE | Q15: 8000 | S15: AT&T | T15: Silver | U15: 1500 | V15: JG-N
A16: Entergy | B16: Platinum | C16: 5000 | D16: 5000 | E16: BL-N | J16: 46010 | K16: 5000 | P16: JE-N | Q16: 5850 | S16: Bank OZK | T16: Silver | U16: 1500
A17: Virco | B17: Platinum | C17: 5000 | D17: 5000 | E17: BL | F17: 12.2.24 | G17: $1,500 in-kind for chair donation + one more table in addition to what they receive as a platinum sponsor. | H17: YES | J17: 1.29.25, 9/2/25, 9/8/25 | K17: =686.25+2813.75+1500 -> 5000 | L17: Scotty Bell, Steve Presley | N17: scottybell@virco.com; stevepresley@virco.com | P17: JE-O | S17: Baptist Health Conway | T17: Platinum | U17: 5000 | V17: JG
A18: Green Bay Packaging | B18: Platinum | C18: 5000 | D18: 5000 | E18: BL | F18: 12.3.24 | H18: YES | J18: 1.30.25 | K18: 5000 | L18: Brad Harville, Christy Prater | N18: bharville@gbp.com, cprater@gbp.com | P18: JG | Q18: 18500 | S18: Cadence Bank | T18: Silver | U18: 1500 | V18: LH
A19: Crafton Tull | B19: Platinum | C19: 5000 | D19: 5000 | E19: BL | F19: 1.10.25 | H19: YES | J19: 1.30.25; 8/18/25 | K19: =2755+1017 -> 3772 | L19: Lane Housley | N19: lane.housley@craftontull.com | P19: JG-N | Q19: 3000 | S19: Catalyst | T19: Platinum | U19: 5000 | V19: LH
J20: 3.19.25 | K20: 1228 | P20: JG-O | S20: Centennial Bank | T20: Gold | U20: 2850 | V20: BL
A21: Baptist Health | B21: Platinum | C21: 5000 | D21: 5000 | E21: JG | F21: 1.13.25 | J21: 3.7.25 | K21: 5000 | L21: April Bennett | P21: LC | Q21: 10000 | S21: Central Baptist College | T21: Silver | U21: 1500 | V21: LH-N
A22: Nabholz | B22: Platinum | C22: 5000 | D22: 5000 | E22: BL | F22: 2.2.25 | J22: 3.11.25 | K22: 5000 | L22: Jake Nabholz | N22: jake.nabholz@nabholz.com | P22: LC-N | Q22: 9000 | S22: Century 21 Sandstone Real Estate Group | T22: Silver | U22: 1500 | V22: LH
A23: Landmark CPAs | B23: Platinum | C23: 5000 | D23: 5000 | E23: LH | F23: 2.14.25 | H23: YES | J23: 6.6.25, 11/12/25 | K23: =241.25+672.5 -> 913.75 | L23: Randy Milligan | N23: RMilligan@landmarkcpas.com | P23: LC-O | S23: Chambers Bank | T23: Silver | U23: 1500 | V23: LC
J24: 6.16.25 | K24: 4086.25 | P24: LH | Q24: 34725 | S24: Cherokee Casino & Hotel Roland + Legends Resort & Casino | T24: Awards | U24: 5000 | V24: LH
A25: GARVER | B25: Platinum | C25: 5000 | D25: 5000 | E25: JG | F25: 2.18.25 | J25: 3.5.25 | K25: 5000 | L25: Dustin Tackett | N25: DLTackett@GarverUSA.com | P25: LH-N | Q25: 24500 | S25: Chick-fil-A | T25: Silver | U25: 1500 | V25: LH
A26: Trinity Development | B26: Platinum | C26: 5000 | D26: 5000 | E26: LH | F26: 2.26.25 | J26: 4.7.25 | K26: 5000 | L26: Courtnie Pledger | N26: cpledger@trinitydevelopmentinc.com | P26: LH-O | Q26: 12850 | S26: Chris Crain Enterprises | T26: Gold | U26: 2850 | V26: BL-N
A27: Cousins' Office Furniture | B27: Platinum | C27: 5000 | D27: 3500 | E27: LH | F27: 2.26.25 | J27: 3.24.25 | K27: 3500 | L27: Adam Robertson, Tara Robertson | N27: adam@cousinsfurniture.com; tara@cousinsfurniture.com | P27: (blank) | Q27: 7375 | S27: Cintas | T27: Gold | U27: 2450 | V27: LH
A28: Clayton Conway | B28: Platinum | C28: 5000 | D28: 4000 | E28: CP-N | F28: 2.28.25 | G28: All communications – Jamar Murchison – jamar.murchison@claytonhomes.com All communications – Stephanie Amerson – stephanie.amerson@claytonhomes.com Billing – Jake Turpin – jake.turpin@claytonhomes.com | J28: 45902 | K28: 4000 | L28: Jake Turpin | N28: jake.turpin@claytonhomes.com | P28: MM | Q28: 1500 | S28: City of Conway | T28: Silver | U28: 1500
A29: Tipton Hurst | B29: Floral | C29: 5000 | D29: 0 | G29: in-kind | P29: TP-N | Q29: 0 | S29: Coldwell Banker RPM: Lori Quinn & Velda Lueders | T29: Silver | U29: 1500 | V29: BL
A30: Conway Corp. | B30: Photo Booth | C30: 7500 | D30: 7500 | E30: BL | F30: 12.12.24 | H30: YES | J30: 3.24.25 | K30: 7500 | L30: Crystal Kemp | N30: Crystal.Kemp@conwaycorp.com | P30: KW-N | Q30: 1500 | S30: Colliers | T30: Silver | U30: 1500 | V30: BL
A31: Insight | B31: Awards | C31: 5000 | D31: 4000 | E31: CP-N | F31: 2.19.25 | H31: YES | J31: 2.28.25 | K31: 4000 | L31: Steven Tyler, Jenny Vallas | N31: steven.tyler@insight.com; jenny.vallas@insight.com | P31: TOTAL | Q31: 293000 | S31: Conductor | T31: Gold | U31: 2850 | V31: LH-N
S32: Conway Behavioral Health | T32: Silver | U32: 1500 | V32: LH
A33: Log Cabin Democrat | B33: Media | C33: 5000 | D33: 4000 | E33: JG | F33: 2.13.25 | J33: 3.27.25 | K33: 4000 | S33: Conway Corporation | T33: Photo Booth | U33: 7500 | V33: BL
A34: Crain Team | B34: Power Hour | C34: 20000 | D34: 15000 | E34: BL | F34: 1.7.25 | G34: Visit with Drew to determine which dealership(s) will be incorporated and how to handle billing. | J34: 4.14.25 | K34: 15000 | L34: Drew Dees, Christian Crain, Cameron Burdess, Justin Kervin | M34: Cameron: 501-339-1492 Justin: 501-687-3945 | N34: ddees@ltdconnect.com; christiancrain@crainteam.net; cameronburdess@crainteam.net; justinkervin@crainteam.net | S34: Conway Regional | T34: Underwriter | U34: 10000 | V34: BL
A35: Tommy's Express | B35: Arrival | C35: 5000 | D35: 5000 | E35: JE | F35: 12.16.24 | H35: YES | J35: 2.24.25 | K35: 5000 | L35: Kason Kimbrell | N35: kasonk@advancedwashnetwork.com | S35: Conway Wealth Management | T35: Silver | U35: 1500 | V35: BL
B36: Awards Reception | C36: 2500 | S36: Corco | T36: Silver | U36: 1500 | V36: BL-N
B37: Awards Reception | C37: 2500 | S37: Cousins' Office Furniture | T37: Speaker Reception | U37: 3500 | V37: LH
A38: Lake Liquor | B38: Beverage | C38: 2500 | D38: 2500 | E38: LC | F38: 3.6.25 | G38: Plus alcohol, no tables | S38: Covington Companies | T38: Silver | U38: 1500 | V38: BL
A39: Chris Crain Enterprises | B39: Gold | C39: 2850 | D39: 2850 | E39: BL | F39: 11.20.24 | G39: Confirm with NK/BB which Chris Crain Enterprises company/companies will be featured on event. | J39: 5.5.25 | K39: 2850 | L39: Brett Berry, Nita Kat Freeman | N39: brettberry@chriscraingroup.com; nitafreeman@chriscraingroup.com | S39: Crafton Tull | T39: Platinum | U39: 5000 | V39: BL
A40: Rogers Group | B40: Gold | C40: 2850 | D40: 2850 | E40: BL | F40: 1.3.25 | J40: 2.24.25 | K40: 2850 | L40: Mike Connelly | N40: mike.connelly@rogersgroupinc.com | S40: Crain Team | T40: Power Hour | U40: 15000 | V40: BL-N
A41: Simmons Bank | B41: Gold | C41: 2850 | D41: 2850 | E41: BL | F41: 1.2.25 | J41: 3.7.25 | K41: 2850 | L41: Justin McCarty | N41: justin.mccarty@simmonsbank.com | S41: Cromwell Architects | T41: Silver | U41: 1500 | V41: JG-N
...

Sheet Baggo for Business
A1: BAGGO FOR BUSINESS | B1: 2025 | S1: BAGGO FOR BUSINESS | T1: 2024
A2: Total Sponsorship Amount Sold | B2: =SUM(D9:D74) -> 29800 | G2: 2026: Rhea Lana's waive 2 teams | K2: OUTSTANDING | S2: Total Sponsorship Amount Sold | T2: =SUM(U9:U54) -> 29300
A3: Budget Goal | B3: 20000 | K3: =MIN(K62-B2) -> -2000 | S3: Budget Goal | T3: 17500
A4: Remaining Balance | B4: =MIN(B2-B3) -> 9800 | K4: =K62/B2 -> 0.93288591 | S4: Remaining Balance | T4: =MIN(T2-T3) -> 11800
A5: Stretch Goal | B5: 32000 | S5: Stretch Goal | T5: 27000
A6: Remaining Balance | B6: =MIN(B2-B5) -> -2200 | S6: Remaining Balance | T6: =MIN(T2-T5) -> 2300
A8: SPONSOR NAME | B8: SPONSORSHIP | C8: COST | D8: PRICE PLEDGED | E8: SOLD BY | F8: DATE SOLD | G8: NOTES | H8: SPECIAL BILLING | I8: INVOICED | J8: DATE PAID | K8: PAID AMOUNT | L8: CONTACT | M8: PHONE | N8: EMAIL | P8: SOLD BY | Q8: PLEDGED | S8: SPONSOR NAME | T8: SPONSORSHIP | U8: PRICE PLEDGED | V8: SOLD BY
A9: American Safeguard Insurance | B9: Title | C9: 5000 | D9: 5000 | E9: LH | F9: 12.23.24 | H9: YES | J9: 4.9.25 | K9: 4027.5 | L9: Jeremy Davis, Jason Smith, Brittney Gwatney | N9: jdavis@asiagents.com; jsmith@asiagents.com; bgwatney@asiagents.com | P9: BL | Q9: 5150 | S9: AFCU | T9: Silver | U9: 350
J10: 7.28.25 | K10: 972.5 | P10: BL-N | Q10: 4000 | S10: American Safeguard Insurance | T10: Title | U10: 5000 | V10: LH
A11: Turbare | B11: Presenting | C11: 2500 | D11: 2500 | E11: BL-N | F11: 1.3.25 | G11: 8 players | H11: YES | J11: 46008 | K11: 500 | L11: Laura Martin, Andria White | N11: ceo@turbare.org; awhite@turbare.org | P11: BL-O | S11: Andy's Frozen Custard | T11: Silver | U11: 350 | V11: LH-N
A12: HD Roofing | B12: Presenting | C12: 2500 | D12: 2500 | E12: LC | F12: 8.7.25 | I12: 8/15/25 GB | J12: 45931 | K12: 2500 | L12: Amber Watkins | N12: office@hdroofing-construction.com | P12: CP | Q12: 1100 | S12: Bank OZK | T12: Silver | U12: 400
A13: Rock City Outfitters | B13: T-Shirt | C13: 1500 | D13: 1000 | E13: LC | F13: 2.24.25 | I13: 7/17/25 GB | J13: 45910 | K13: 1000 | L13: Ryan Ritchie | N13: ryan@rockcityoutfitters.com | P13: CP-N | Q13: 600 | S13: Bledsoe Chiropractic | T13: Gold | U13: 600 | V13: LC
A14: Farris Agency | B14: Lunch | C14: 1000 | D14: 1000 | E14: JE | F14: 12.4.24 | I14: 7/17/25 GB | J14: 7.25.25 | K14: 1000 | L14: Alan White, Travis Mulhearn, Christina Horn | N14: alan@farrisagency.com travis@farrisagency.com christina@farrisagency.com | P14: CP-O | S14: Cadence Bank | T14: Silver | U14: 350 | V14: LH-N
A15: Smith Ford | B15: Lunch | C15: 1000 | D15: 1000 | E15: BL | F15: 2.1.25 | I15: 7/17/25 GB | J15: 45917 | K15: 1000 | L15: Cate McConnell | N15: cate.mcconnell@smithford.com | P15: JE | Q15: 1850 | S15: Chambers Bank | T15: Gold | U15: 600 | V15: LC-N
A16: Cross Creek Sandwich Shop | B16: Lunch | C16: 1000 | D16: 0 | E16: LC | F16: 4.28.25 | G16: in-kind for food | I16: 0 | K16: 0 | L16: Caitlin Bailey | N16: crosscreekcaitlin@gmail.com | P16: JE-N | Q16: 350 | S16: Chris Crain Enterprises | T16: Silver | U16: 0 | V16: BL
A17: RE/MAX Elite: The Emily Walter Team | B17: Baggo Brews | C17: 1000 | D17: 1000 | E17: LC-N | F17: 2.7.25 | I17: 7/17/25 GB | J17: 45911 | K17: 1000 | L17: Emily Walter | N17: emilywalterrealtor@gmail.com | P17: JE-O | S17: City of Conway | T17: Silver | U17: 0
A18: Car-Son Construction | B18: Baggo Brews | C18: 1000 | D18: 1000 | E18: BL-N | F18: 2.28.25 | G18: 2 teams, 4 players total | H18: YES | J18: 45950 | K18: 1000 | L18: Brad Fason, Brian Fason | N18: bfason@car-son.com; bradfason@car-son.com | P18: JG | S18: Conway Regional | T18: Gold | U18: 500 | V18: BL
A19: Rouge Roundabout | B19: Baggo Brews | C19: 1000 | D19: 0 | F19: 8.21.25 | G19: in-kind for alcohol | I19: 0 | K19: 0 | P19: JG-N | Q19: 0 | S19: Crain Team | T19: Silver | U19: 0 | V19: BL-N
A20: Dyermark | B20: Photo Booth | C20: 1000 | D20: 1000 | E20: LC | F20: 2.11.25 | H20: YES | J20: 9/16/2025, 10/13/25, 11/18/25 | K20: =112.5+512.5+375 -> 1000 | L20: Ali Dyer | N20: ali@dyermark.com | P20: JG-O | S20: Cross Creek Sandwich Shop | T20: Lunch | U20: 0 | V20: LC-N
A21: Green Bay Packaging | B21: Gold | C21: 600 | D21: 500 | E21: BL | F21: 12.3.24 | H21: YES | I21: 0 | J21: 6.5.25 | K21: 500 | L21: Brad Harville, Christy Prater | N21: bharville@gbp.com, cprater@gbp.com | P21: LC | Q21: 6050 | S21: Diamond State Restoration | T21: Gold | U21: 600 | V21: LC-N
A22: Conway Regional | B22: Gold | C22: 600 | D22: 500 | E22: BL | F22: 12.30.24 | I22: 7/17/25 GB | J22: 7.23.25 | K22: 500 | L22: Rebekah Fincher | N22: rfincher@conwayregional.org | P22: LC-N | Q22: 3000 | S22: DKM Construction | T22: Gold | U22: 600 | V22: CP-N
A23: Simmons Bank | B23: Gold | C23: 600 | D23: 500 | E23: BL | F23: 1.2.25 | I23: 7/17/25 GB | J23: 7.28.25 | K23: 500 | L23: Justin McCarty | N23: justin.mccarty@simmonsbank.com | P23: LC-O | S23: Dyermark | T23: Photo Booth | U23: 1000 | V23: LC-N
A24: Insight | B24: Gold | C24: 600 | D24: 500 | E24: CP | F24: 2.19.25 | H24: YES | I24: 0 | J24: 4.8.25 | K24: 500 | L24: Steven Tyler, Jenny Vallas | N24: steven.tyler@insight.com; jenny.vallas@insight.com | P24: LH | Q24: 5700 | S24: Engage Management | T24: Silver | U24: 350 | V24: BL-N
A25: Sowell Ferris Architects | B25: Gold | C25: 600 | D25: 600 | E25: LH-O | F25: 2.18.25 | I25: 7/17/25 GB | J25: 45903 | K25: 600 | L25: Cody Ferris, Emily Ferris | N25: cody@sowellarchitects.com; emily@sowellarchitects.com | P25: LH-N | S25: Farris Agency | T25: Lunch | U25: 1000 | V25: JE-N
A26: Sinco | B26: Gold | C26: 600 | D26: 600 | E26: CP | F26: 2.21.25 | H26: YES | J26: 45888 | K26: 600 | L26: Parker Spradlin, Grey Williams, Rhonda Wilson | N26: Pspradlin@sincoinc.com; gwilliams@sincoinc.com; rwilson@sincoinc.com | P26: LH-O | Q26: 950 | S26: First Arkansas Bank & Trust | T26: Silver | U26: 0 | V26: LH
A27: Entergy | B27: Gold | C27: 600 | D27: 600 | E27: CP-N | F27: 2.26.25 | G27: Region Construction team will pay for this, so invoice James Warren | I27: 7/17/25 GB | J27: 7.17.25 | K27: 600 | L27: Zack Hale, James Warren | N27: zhale@entergy.com; jwarren@entergy.com | P27: (blank) | Q27: 1050 | S27: First Community Bank | T27: Gold | U27: 500 | V27: BL
A28: Chambers Bank | B28: Gold | C28: 600 | D28: 600 | E28: LC | F28: 2.27.25 | I28: 7/17/25 GB | J28: 7.22.25 | K28: 600 | L28: Ethan Barnes | N28: ebarnes@chambers.bank | P28: TOTAL | Q28: 29800 | S28: First Security Bank | T28: Gold | U28: 500 | V28: BL
A29: State Farm Jay Bernard | B29: Gold | C29: 600 | D29: 500 | E29: BL-N | F29: 2.28.25 | H29: YES | I29: 0 | J29: 3.19.25 | K29: 500 | L29: Jay Bernard | N29: jay.bernard.l8if@statefarm.com | S29: Green Bay Packaging | T29: Gold | U29: 500 | V29: BL
A30: Bledsoe Chiropractic | B30: Gold | C30: 600 | D30: 600 | E30: LC | F30: 3.19.25 | H30: YES | I30: 0 | J30: 6.16.25 | K30: 600 | L30: Amanda Bledsoe, Sarah Lockard | N30: dramandabledsoe@gmail.com; sarah@bledsoechiropractic.com | S30: HD Roofing | T30: Presenting | U30: 2500 | V30: LC
A31: First Security Bank | B31: Gold | C31: 600 | D31: 500 | E31: BL | F31: 3.19.25 | I31: 7/17/25 GB | J31: 45925 | K31: 500 | L31: Stefanie Vann | N31: stefanie.vann@fsbank.com | S31: Insight | T31: Gold | U31: 500 | V31: CP
A32: Molex | B32: Gold | C32: 600 | D32: 1800 | E32: BL | F32: 3.28.25 | I32: 7/17/25 GB | J32: 45905 | K32: 1800 | L32: Cory Ensley | N32: cory.ensley@molex.com | S32: Jakob Henry | T32: Silver | U32: 350 | V32: JE-N
A33: Pro-Land Title | B33: Gold | C33: 600 | D33: 600 | E33: LC-N | F33: 4.11.25 | I33: 7/17/25 GB | J33: 45910 | K33: 600 | L33: Brooklyn Cardin | N33: bcardin@prolandtitle.com | S33: Lake Liquor | T33: Baggo Brews | U33: 1000 | V33: LC
B34: Gold | C34: 600 | S34: Malvern National Bank | T34: Silver | U34: 200 | V34: LH
B35: Gold | C35: 600 | S35: Market Place Grill | T35: Silver | U35: 350 | V35: JE-N
A36: Arkansas Federal Credit Union | B36: Silver | C36: 350 | D36: 350 | E36: LH-O | F36: 8.28.25 | G36: One team from 10:00 - 12:00: Tiffany Mitchell and Sidney Foltz | I36: 9/4/25 GB | J36: 45917 | K36: 350 | L36: Denise Goforth | N36: dgoforth@arcu.org | S36: Molex | T36: Gold | U36: 1800 | V36: BL-N
A37: Chris Crain Enterprises | B37: Silver | C37: 350 | D37: 0 | E37: BL | F37: 11.20.24 | G37: Confirm with NK/BB which Chris Crain Enterprises company/companies will be featured on event. | I37: 0 | L37: Brett Berry, Nita Kat Freeman | N37: brettberry@chriscraingroup.com; nitafreeman@chriscraingroup.com | S37: Ott Insurance | T37: Gold | U37: 600 | V37: LC
A38: Rhea Lana's | B38: Silver | C38: 350 | D38: 0 | E38: LH-O | F38: 45620 | G38: 2 Teams | I38: 0 | L38: Rhea Lana Riner, Hannah Johnson, Abbie Kent | N38: rhealana@rhealana.com; hannahjohnson@rhealana.com; abbie@rhealana.com | S38: Paladino Nash | T38: Silver | U38: 0 | V38: LH-N
A39: First Arkansas Bank & Trust | B39: Silver | C39: 350 | D39: 0 | E39: LH | F39: 12.9.24 | I39: 0 | L39: John Simmons, Roger Sundermeier, Mark Wilson, Jessica Pint | N39: jsimmons@fabandt.bank; rsundermeier@fabandt.bank; mwilson@fabandt.bank; jpint@fabandt.bank | S39: Pro Ridge Roofing | T39: Silver | U39: 350 | V39: LC-N
A40: Crain Team | B40: Silver | C40: 350 | D40: 0 | E40: BL | F40: 1.7.25 | G40: 2 teams - one for each dealership | I40: 0 | L40: Drew Dees, Christian Crain, Cameron Burdess, Justin Kervin | M40: Cameron: 501-339-1492 Justin: 501-687-3945 | N40: ddees@ltdconnect.com; christiancrain@crainteam.net; cameronburdess@crainteam.net; justinkervin@crainteam.net | S40: Rhea Lana's | T40: Silver | U40: 700 | V40: JE-N
A41: Engage Management | B41: Silver | C41: 350 | D41: 350 | E41: BL | F41: 2.2.25 | I41: 7/17/25 GB | J41: 45880 | K41: 350 | L41: Morgan Lefler | N41: morgan.lefler@engagemanagement.com | S41: Rock City Outfitters | T41: T-Shirt | U41: 1000 | V41: LC
...

Sheet Biketoberfest
A1: BIKETOBERFEST | B1: 2025 | S1: BIKETOBERFEST | T1: 2024
A2: Total Sponsorship Amount Sold | B2: =SUM(D9:D45) -> 24000 | K2: OUTSTANDING | S2: Total Sponsorship Amount Sold | T2: =SUM(U9:U28) -> 32250
A3: Budget Goal | B3: 30000 | K3: =MIN(K30-B2) -> -2500 | S3: Budget Goal | T3: 30000
A4: Remaining Balance | B4: =MIN(B2-B3) -> -6000 | K4: =K30/B2 -> 0.89583333 | S4: Remaining Balance | T4: =MIN(T2-T3) -> 2250
A5: Stretch Goal | B5: 35000 | S5: Stretch Goal | T5: 40000
A6: Remaining Balance | B6: =MIN(B2-B5) -> -11000 | S6: Remaining Balance | T6: =MIN(T2-T5) -> -7750
A8: SPONSOR NAME | B8: SPONSORSHIP | C8: COST | D8: PRICE PLEDGED | E8: SOLD BY | F8: DATE SOLD | G8: NOTES | H8: SPECIAL BILLING | I8: INVOICED | J8: DATE PAID | K8: PAID AMOUNT | L8: CONTACT | M8: PHONE | N8: EMAIL | P8: SOLD BY | Q8: PLEDGED | S8: SPONSOR NAME | T8: SPONSORSHIP | U8: PRICE PLEDGED | V8: SOLD BY
A9: Conway Regional | B9: Title | C9: 10000 | D9: 7500 | E9: BL | F9: 12.30.24 | I9: 9/17/25 GB | J9: 45924 | K9: 7500 | L9: Rebekah Fincher | N9: rfincher@conwayregional.org | P9: BL | Q9: 15000 | S9: Caldwell Toyota | T9: Presenting | U9: 5000 | V9: JG-N
A10: Caldwell Toyota | B10: Presenting | C10: 5000 | D10: 4000 | E10: JG-N | F10: 12.20.24 | I10: 9/25/25 GB | J10: 45936 | K10: 4000 | L10: Jay Caldwell | N10: jay@caldwellcares.com | P10: BL-N | S10: Conway Regional | T10: Title | U10: 7500 | V10: BL
A11: Meridian Investment Advisors | B11: Presenting | C11: 5000 | D11: 5000 | E11: LH | F11: 3.19.25 | I11: 9/17/25 GB | J11: 45917 | K11: 5000 | L11: Pat Moon | N11: pmoon@meridiania.com | P11: BL-O | S11: Cousins' Office Furnitre | T11: Taco Ride | U11: 0 | V11: LH-N
B12: Presenting | C12: 5000 | P12: CP | S12: Crafton Tull | T12: Route | U12: 2500 | V12: BL
B13: Presenting | C13: 5000 | P13: CP-N | S13: Engage Management | T13: Route | U13: 2500 | V13: BL
B14: Presenting | C14: 5000 | P14: CP-O | S14: First Security Bank | T14: Route | U14: 2500 | V14: BL
B15: Themed Ride #1 | C15: 3000 | P15: JE | S15: Home2/Hilton Garden Inn | T15: Route | U15: 1000 | V15: JE
B16: Themed Ride #1 | C16: 3000 | P16: JE-N | S16: Meridian Investment Advisors | T16: Presenting | U16: 5000 | V16: LH
B17: Themed Ride #2 | C17: 3000 | P17: JE-O | S17: Point Remove Brewing | T17: Bike, Brunch & Brews | U17: 3750 | V17: LH
B18: Themed Ride #2 | C18: 3000 | P18: JG | S18: Rogers Group | T18: Route | U18: 2500 | V18: BL
B19: Themed Ride #3 | C19: 3000 | P19: JG-N | Q19: 4000 | S19: Rogue Roundabout | T19: Kick-off Ride | U19: 0 | V19: LH
B20: Themed Ride #3 | C20: 3000 | P20: JG-O | S20: The Ride | T20: Ride Partner | U20: 0
A21: Rogers Group | B21: Route | C21: 2500 | D21: 2500 | E21: BL | F21: 1.3.25 | I21: 9/17/25 GB | J21: 45930 | K21: 2500 | L21: Mike Connelly | N21: mike.connelly@rogersgroupinc.com | P21: LC
A22: Crafton Tull | B22: Route | C22: 2500 | D22: 2500 | E22: BL | F22: 1.10.25 | H22: YES | J22: 45980 | K22: 2500 | L22: Lane Housley | N22: lane.housley@craftontull.com | P22: LC-N
A23: Engage Management | B23: Route | C23: 2500 | D23: 2500 | E23: BL | F23: 2.2.25 | I23: 9/17/25 GB | L23: Morgan Lefler | N23: morgan.lefler@engagemanagement.com | P23: LC-O
A24: Cousins' | B24: Route | C24: 2500 | D24: 0 | E24: LH | F24: 2.26.25 | G24: in-kind for hauling event materials | I24: 0 | L24: Adam Robertson, Tara Robertson | N24: adam@cousinsfurniture.com; tara@cousinsfurniture.com | P24: LH | Q24: 5000
B25: Virtual Ride | C25: 2500 | P25: LH-N
B26: Virtual Ride | C26: 2500 | P26: LH-O
P27: (blank)
P28: TOTAL | Q28: 24000
K30: =SUM(K9:K29) -> 21500
E300: BL-O
E301: BL-N
E302: BL
E303: CP-O
E304: CP-N
E305: CP
E306: JG-O
E307: JG-N
E308: JG
E309: JE-O
E310: JE-N
E311: JE
...

Sheet Bowling for Business
A1: BOWLING FOR BUSINESS | B1: 2025 | S1: BOWLING FOR BUSINESS | T1: 2024
A2: Total Sponsorship Amount Sold | B2: =SUM(D9:D69) -> 27650 | G2: 2026: Rhea Lana's waive 2 teams | K2: OUTSTANDING | S2: Total Sponsorship Amount Sold | T2: =SUM(U9:U67) -> 30250
A3: Budget Goal | B3: 20000 | K3: =MIN(K69-B2) -> 0 | S3: Budget Goal | T3: 17500
A4: Remaining Balance | B4: =MIN(B2-B3) -> 7650 | K4: =K69/B2 -> 1 | S4: Remaining Balance | T4: =MIN(T2-T3) -> 12750
A5: Stretch Goal | B5: 34000 | S5: Stretch Goal | T5: 30000
A6: Remaining Balance | B6: =MIN(B2-B5) -> -6350 | S6: Remaining Balance | T6: =MIN(T2-T5) -> 250
A8: SPONSOR NAME | B8: SPONSORSHIP | C8: COST | D8: PRICE PLEDGED | E8: SOLD BY | F8: DATE SOLD | G8: NOTES | H8: SPECIAL BILLING | I8: INVOICED | J8: DATE PAID | K8: PAID AMOUNT | L8: CONTACT | M8: PHONE | N8: EMAIL | P8: SOLD BY | Q8: PLEDGED | S8: SPONSOR NAME | T8: SPONSORSHIP | U8: PRICE PLEDGED | V8: SOLD BY
B9: Title | C9: 5000 | P9: BL | Q9: 5500 | S9: Acxiom | T9: Lane | U9: 1000 | V9: BL-N
A10: Superior Plumbing | B10: Presenting | C10: 2500 | D10: 2500 | E10: LC | F10: 4.23.25 | J10: 6.17.25 | K10: 2500 | L10: Dustin Smith | N10: DUSTIN.SMITH@SUPERIORPLUMBINGAR.COM | P10: BL-N | Q10: 2700 | S10: Alpha Countertops | T10: Lane | U10: 600 | V10: LC-N
B11: Presenting | C11: 2500 | P11: BL-O | S11: American Safeguard Insurance | T11: Team | U11: 0 | V11: LH
A12: Rock City Outfitters | B12: T-Shirt | C12: 1500 | D12: 1000 | E12: LC | F12: 2.24.25 | J12: 6.30.25 | K12: 1000 | L12: Ryan Ritchie | N12: ryan@rockcityoutfitters.com | P12: CP | Q12: 1800 | S12: Andy's Frozen Custard | T12: Lane | U12: 600 | V12: LH-N
A13: Turbare | B13: Meal | C13: 1000 | D13: 1350 | E13: BL-N | F13: 1.3.25 | G13: Meal sponsor + one additional team, 2 teams of 5 | H13: YES | J13: 7.7.25 | K13: 1350 | L13: Laura Martin, Andria White | N13: ceo@turbare.org; awhite@turbare.org | P13: CP-N | Q13: 600 | S13: Arkansas Roofing Kompany | T13: Presenting | U13: 2500 | V13: LC
A14: Insight | B14: Meal | C14: 1000 | D14: 1200 | E14: CP | F14: 2.19.25 | G14: Include lane signage and two teams of five | H14: YES | J14: 4.8.25 | K14: 1200 | L14: Steven Tyler, Jenny Vallas | N14: steven.tyler@insight.com; jenny.vallas@insight.com | P14: CP-O | S14: Attorney's Title Group | T14: Team | U14: 350 | V14: LC-N
B15: Meal | C15: 1000 | P15: JE | Q15: 2250 | S15: B&A Property Maintenance | T15: Team | U15: 300
A16: Car-Son Construction | B16: Beverage | C16: 1000 | D16: 1000 | E16: BL-N | F16: 2.28.25 | H16: YES | J16: 6.9.25 | K16: 1000 | L16: Brad Fason, Brian Fason | N16: bfason@car-son.com; bradfason@car-son.com | P16: JE-N | Q16: 1050 | S16: Bank OZK | T16: Team | U16: 450
A17: Fair and Company | B17: Beverage | C17: 1000 | D17: 1000 | E17: LC | F17: 5.7.25 | J17: 6.20.25 | K17: 1000 | L17: Nick Schroeder | N17: nschroeder@fairandcompany.com | P17: JE-O | S17: Bledsoe Chiropractic | T17: Lane | U17: 600 | V17: LC
A18: Conway Family Dental | B18: Photo Booth | C18: 1000 | D18: 1000 | E18: BL | F18: 5.30.25 | J18: 6.2.25 | K18: 1000 | P18: JG | S18: Chambers Bank | T18: Lane | U18: 600 | V18: LC-N
A19: Green Bay Packaging | B19: Lane | C19: 600 | D19: 500 | E19: BL | F19: 12.3.24 | H19: YES | J19: 45903 | K19: 500 | L19: Brad Harville, Christy Prater | N19: bharville@gbp.com, cprater@gbp.com | P19: JG-N | Q19: 0 | S19: Chris Crain Enterprises | T19: Team | U19: 0 | V19: BL-N
A20: Farris Agency | B20: Lane | C20: 600 | D20: 600 | E20: JE | F20: 12.4.24 | J20: 5.16.25 | K20: 600 | L20: Alan White, Travis Mulhearn, Christina Horn | N20: alan@farrisagency.com travis@farrisagency.com christina@farrisagency.com | P20: JG-O | S20: City of Conway | T20: Team | U20: 0
A21: Hampton Inn & Suites | B21: Lane | C21: 600 | D21: 600 | E21: JE | F21: 12.19.24 | J21: 6.23.25 | K21: 600 | L21: Allan Gammill | N21: allan.gammill@hilton.com | P21: LC | Q21: 7350 | S21: Conway Corp. | T21: Team | U21: 300
A22: Conway Regional | B22: Lane | C22: 600 | D22: 500 | E22: BL | F22: 12.30.24 | J22: 5.22.25 | K22: 500 | L22: Rebekah Fincher | N22: rfincher@conwayregional.org | P22: LC-N | Q22: 3950 | S22: Conway Family Dental | T22: Photo Booth | U22: 1000 | V22: BL-N
A23: Rogers Group | B23: Lane | C23: 600 | D23: 500 | E23: BL | F23: 1.3.25 | J23: 6.16.25 | K23: 500 | L23: Mike Connelly | N23: mike.connelly@rogersgroupinc.com | P23: LC-O | S23: Conway Fire Department | T23: Team | U23: 0
A24: Simmons Bank | B24: Lane | C24: 600 | D24: 500 | E24: BL | F24: 1.2.25 | J24: 7.14.25 | K24: 500 | L24: Justin McCarty | N24: justin.mccarty@simmonsbank.com | P24: LH | Q24: 0 | S24: Conway Regional | T24: Lane | U24: 500 | V24: BL
A25: Acxiom | B25: Lane | C25: 600 | D25: 1000 | E25: BL | F25: 1.8.25 | J25: 6.12.25 | K25: 1000 | L25: Crystal Floyd, Alison Cowles | N25: Crystal.Floyd@acxiom.com; Alison.Cowles@acxiom.com | P25: LH-N | Q25: 2000 | S25: Crain Team | T25: Team | U25: 0 | V25: BL-N
A26: WACO Title | B26: Lane | C26: 600 | D26: 600 | E26: LC-N | F26: 2.7.25 | J26: 5.19.25 | K26: 600 | L26: Ryke Dismuke, Brooklyn Burnett | N26: idismuke@wacotitle.com: bburnett1@wacotitle.com | P26: LH-O | S26: Dave Creek Media | T26: Team | U26: 300 | V26: JG
A27: Dyermark | B27: Lane | C27: 600 | D27: 600 | E27: LC | F27: 2.11.25 | H27: YES | J27: 6.17.25 | K27: 175 | L27: Ali Dyer | N27: ali@dyermark.com | P27: (blank) | Q27: 450 | S27: Diamond State Restoration | T27: Lane | U27: 600 | V27: LC-N
J28: 4.25.25 | K28: 425 | P28: TOTAL | Q28: 27650 | S28: DKM Construction | T28: Lane | U28: 600 | V28: CP-N
A29: Sowell Ferris Architects | B29: Lane | C29: 600 | D29: 600 | E29: LH-N | F29: 2.18.25 | J29: 5.27.25 | K29: 600 | L29: Cody Ferris, Emily Ferris | N29: cody@sowellarchitects.com; emily@sowellarchitects.com | S29: Douglas Companies | T29: Team | U29: 0
A30: Sinco | B30: Lane | C30: 600 | D30: 600 | E30: CP | F30: 2.21.25 | H30: YES | J30: 6.9.25, 8/19/25 | K30: 600 | L30: Parker Spradlin, Grey Williams, Rhonda Wilson | N30: Pspradlin@sincoinc.com; gwilliams@sincoinc.com; rwilson@sincoinc.com | S30: Dyermark | T30: Lane | U30: 600 | V30: LC-N
A31: Entergy | B31: Lane | C31: 600 | D31: 600 | E31: CP-N | F31: 2.26.25 | G31: Region Construction team will pay for this, so invoice James Warren | J31: 6.10.25 | K31: 600 | L31: Zack Hale, James Warren | N31: zhale@entergy.com; jwarren@entergy.com | S31: Edward Jones, Stacey Alston | T31: Team | U31: 350 | V31: LC
A32: Chambers Bank | B32: Lane | C32: 600 | D32: 600 | E32: LC | F32: 2.27.25 | J32: 5.12.25 | K32: 600 | L32: Ethan Barnes | N32: ebarnes@chambers.bank | S32: Engage Management | T32: Team | U32: 350 | V32: BL-N
A33: State Farm Jay Bernard | B33: Lane | C33: 600 | D33: 500 | E33: BL | F33: 2.28.25 | H33: YES | J33: 3.19.25 | K33: 500 | L33: Jay Bernard | N33: jay.bernard.l8if@statefarm.com | S33: Fair & Company | T33: Drink | U33: 1000 | V33: LC-N
A34: Bledsoe Chiropractic | B34: Lane | C34: 600 | D34: 600 | E34: LC | F34: 3.19.25 | H34: YES | J34: 6.16.25 | K34: 600 | L34: Amanda Bledsoe, Sarah Lockard | N34: dramandabledsoe@gmail.com; sarah@bledsoechiropractic.com | S34: Farris Agency | T34: Lane | U34: 600 | V34: JE-N
A35: Pro-Land Title | B35: Lane | C35: 600 | D35: 600 | E35: LC-N | F35: 4.11.25 | J35: 5.30.25 | K35: 600 | L35: Brooklyn Cardin | N35: bcardin@prolandtitle.com | S35: First Arkansas Bank & Trust | T35: Team | U35: 0 | V35: LH
A36: Window Depot | B36: Lane | C36: 600 | D36: 600 | E36: LC-N | F36: 4.21.25 | J36: 5.21.25 | K36: 600 | L36: Zack Venable, Karen | N36: zack@windowdepotar.com; office.windowdepotar@gmail.com | S36: First Community Bank | T36: Lane | U36: 500 | V36: BL
A37: Westport Dental | B37: Lane | C37: 600 | D37: 1200 | E37: LC-N | F37: 5.9.25 | G37: Noon/lunch flight, t-shirt sizes: 1 - XL, 4 - L, 7 - M, Leo said we can charge for the additional shirts. | J37: 6.2.25 | K37: 1200 | L37: Cyndi Winter | N37: cwinter.westport@conwaycorp.net | S37: First Security Bank | T37: Team | U37: 300 | V37: BL-O
A38: Nabco | B38: Lane | C38: 600 | D38: 600 | E38: LC-N | F38: 5.29.25 | J38: 6.25.25 | K38: 600 | L38: Dusty Brand | N38: cbrand@nabco.com | S38: Green Bay Packaging | T38: Lane | U38: 500 | V38: BL
A39: Stonebridge | B39: Team | C39: 350 | D39: 350 | E39: JE-N | F39: 3.10.25 | J39: 6.9.25 | K39: 350 | L39: Shelley Culwell | N39: shelley.culwell@sbseniorliving.com | S39: Hampton Inn and Suites | T39: Lane | U39: 600 | V39: JE-N
A40: Chris Crain Enterprises | B40: Team | C40: 350 | D40: 0 | E40: BL | F40: 11.20.24 | G40: Confirm with NK/BB which Chris Crain Enterprises company/companies will be featured on event. | I40: 0 | L40: Brett Berry, Nita Kat Freeman | N40: brettberry@chriscraingroup.com; nitafreeman@chriscraingroup.com | S40: Honda World | T40: Team | U40: 0
A41: Rhea Lana's | B41: Team | C41: 350 | D41: 0 | E41: LH-N | F41: 45597 | G41: 2 teams | I41: 0 | L41: Rhea Lana Riner, Hannah Johnson, Abbie Kent | N41: rhealana@rhealana.com; hannahjohnson@rhealana.com; abbie@rhealana.com | S41: Insight | T41: Lane | U41: 1200 | V41: CP-N
...

Sheet Business Expo & Taste of Conway
A1: BUSINESS EXPO & TASTE OF CONWAY | B1: 2025 | S1: BUSINESS EXPO & TASTE OF CONWAY | T1: 2024
A2: Total Sponsorship Amount Sold | B2: =SUM(D9:D146) -> 99570 | K2: OUTSTANDING | S2: Total Sponsorship Amount Sold | T2: =SUM(U9:U184) -> 117965
A3: Budget Goal | B3: 85000 | K3: =MIN(K146-B2) -> -6395 | S3: Budget Goal | T3: 75000
A4: Remaining Balance | B4: =MIN(B2-B3) -> 14570 | K4: =K146/B2 -> 0.93577383 | S4: Remaining Balance | T4: =MIN(T2-T3) -> 42965
A5: Stretch Goal | B5: 120000 | S5: Stretch Goal | T5: 105000
A6: Remaining Balance | B6: =MIN(B2-B5) -> -20430 | S6: Remaining Balance | T6: =MIN(T2-T5) -> 12965
A8: SPONSOR NAME | B8: SPONSORSHIP | C8: COST | D8: PRICE PLEDGED | E8: SOLD BY | F8: DATE SOLD | G8: NOTES | H8: SPECIAL BILLING | I8: INVOICED | J8: DATE PAID | K8: PAID AMOUNT | L8: CONTACT | M8: PHONE | N8: EMAIL | P8: SOLD BY | Q8: PLEDGED | S8: SPONSOR NAME | T8: SPONSORSHIP | U8: PRICE PLEDGED | V8: SOLD BY
B9: Title | C9: 7500 | P9: BL | Q9: 33620 | S9: 7 Brew | T9: Booth Space | U9: 500
A10: Simmons Bank | B10: Presenting | C10: 5000 | D10: 5000 | E10: BL | F10: 1.2.25 | I10: 7/31/25 GB | J10: 45898 | K10: 5000 | L10: Justin McCarty | N10: justin.mccarty@simmonsbank.com | P10: BL-N | Q10: 500 | S10: 7 Brew | T10: TOC Food Vendor | U10: 0
A11: Cousins' Office Furniture | B11: Presenting | C11: 5000 | D11: 5000 | E11: LH | F11: 2.26.25 | I11: 7/31/25 GB | J11: 45939 | K11: 5000 | L11: Adam Robertson, Tara Robertson | N11: adam@cousinsfurniture.com; tara@cousinsfurniture.com | P11: BL-O | S11: Acxiom | T11: Silver | U11: 1000 | V11: BL
A12: Arkansas Game & Fish Commission | B12: Platinum | C12: 3500 | D12: 3000 | E12: JG | F12: 1.7.25 | I12: 7/31/25 GB | L12: Spencer Griffith | N12: spencer.griffith@agfc.ar.gov | P12: CP | Q12: 1000 | S12: Adams Pest Control | T12: Booth Space | U12: 500 | V12: JE-N
A13: Conductor | B13: Platinum | C13: 3500 | D13: 0 | E13: LH | F13: 1.13.25 | I13: 0 | L13: Grace Rains | N13: grace@arconductor.org | P13: CP-N | Q13: 1250 | S13: Advance Ticket Sales | T13: Tickets | U13: 2460
A14: Dave Creek Media | B14: Platinum | C14: 3500 | D14: 3500 | E14: JG-N | F14: 2.28.25 | G14: Sponsor deliverables per Jamie: 1) We would host a lunch here for Expo participants well in advance of the event so you could share similar content in-person. 2) Break-out session at the Expo. 3) Video commercial that runs during Expo 4) Included in Expo promotion and Social Media. | I14: 7/31/25 GB | J14: 46003 | K14: 3500 | L14: Jakob Michaelis | N14: jakob@davecreekmedia.com | P14: CP-O | S14: All Clean USA | T14: Premier Vendor | U14: 750 | V14: JE-N
A15: CARTI | B15: Platinum | C15: 3500 | D15: 2500 | E15: LC-N | F15: 9.19.25 | G15: Will also have a breakout session. | I15: 9/23/25 GB | J15: 45953 | K15: 2500 | L15: Carroll Jo Malloy | N15: CarrollJo.Malloy@CARTI.com | P15: JE | Q15: 3530 | S15: Alpha Countertops & Tile | T15: Booth Space | U15: 530 | V15: JE-N
A16: DKM Construction | B16: Gold | C16: 2000 | D16: 1000 | E16: CP | F16: 2.17.25 | H16: YES | J16: 45985 | K16: 1000 | L16: Kim Morehart, Daniel Morehart | N16: kimm.dkm@gmail.com; danielm.dkm@gmail.com | P16: JE-N | Q16: 8920 | S16: Ambassadors | T16: 1 Taste, 1 Breakfast OR Lunch, 1 session ticket | U16: 0
A17: Snap-on | B17: Gold | C17: 2000 | D17: 2000 | E17: BL | F17: 3.10.25 | H17: YES | J17: 6.25.25 | K17: 2000 | L17: Scott Champlin, Lynne Sponer | N17: scott.l.champlin@snapon.com; lynne.sponer@snapon.com | P17: JE-O | S17: Andy's Frozen Custard | T17: Booth Space | U17: 500 | V17: LH-N
A18: Pafford | B18: Gold | C18: 2000 | D18: 2500 | E18: BL | F18: 7.1.25 | I18: 7/31/25 GB | J18: 45895 | K18: 2500 | L18: Dylan Kelsey | P18: JG | Q18: 5600 | S18: Andy's Frozen Custard | T18: TOC Food Vendor | U18: 0 | V18: LH
A19: Staley Electric | B19: Gold | C19: 2000 | D19: 2000 | E19: JG-N | F19: 7.3.25 | I19: 7/31/25 GB | J19: 45873 | K19: 2000 | L19: Heather Finch, Matt Benton, Troy Lampley | N19: heather.finch@staleyelectric.com; matt.benton@staleyelectric.com; Troy.Lampley@staleyelectric.com | P19: JG-N | Q19: 6500 | S19: Aramark | T19: TOC Food Vendor | U19: 0 | V19: LH
A20: TGI Friday's Catering | B20: Silver | C20: 1000 | D20: 1000 | E20: JG-N | F20: 10.1.25 | I20: 10/2/25 GB | J20: 45989 | K20: 1000 | L20: Jeremy Gardner | N20: TGIFboss@gmail.com | P20: JG-O | S20: Arisa Health | T20: Premier Vendor | U20: 750 | V20: JE
A21: Arisa Health | B21: Silver | C21: 1000 | D21: 1000 | E21: JE-N | F21: 5.21.25 | I21: 7/31/25 GB | J21: 45950 | K21: 1000 | L21: Teresa Wilson, Brad Hyde | N21: Teresa.wilson@arisahealth.org; brad.hyde@arisahealth.org | P21: LC | Q21: 13105 | S21: Arkansas Division of Services for the Blind | T21: Booth Space | U21: 520 | V21: JE-N
A22: Green Bay Packaging | B22: Silver | C22: 1000 | D22: 1400 | E22: BL | F22: 12.3.24 | H22: YES | J22: 9/3/2025, 11/19/25 | K22: =1251.25+148.75 -> 1400 | L22: Brad Harville, Christy Prater | N22: bharville@gbp.com, cprater@gbp.com | P22: LC-N | Q22: 7000 | S22: Arkansas Game & Fish | T22: Platinum | U22: 3500 | V22: JG
A23: Conway Regional | B23: Silver | C23: 1000 | D23: 1000 | E23: BL | F23: 12.30.24 | I23: 7/31/25 GB | J23: 45924 | K23: 1000 | L23: Rebekah Fincher | N23: rfincher@conwayregional.org | P23: LC-O | S23: Arkansas Secretary of State | T23: Booth Space | U23: 515
A24: Acxiom | B24: Silver | C24: 1000 | D24: 1000 | E24: BL | F24: 1.8.25 | I24: 7/31/25 GB | J24: 45902 | K24: 1000 | L24: Crystal Floyd, Alison Cowles | N24: Crystal.Floyd@acxiom.com; Alison.Cowles@acxiom.com | P24: LH | Q24: 7175 | S24: Arkansas Spine and Pain | T24: Premier Vendor | U24: 750 | V24: JE-N
A25: Crafton Tull | B25: Silver | C25: 1000 | D25: 1000 | E25: BL | F25: 1.10.25 | G25: Wants booth next to Rogers Group | H25: YES | J25: 45980 | K25: 1000 | L25: Lane Housley | N25: lane.housley@craftontull.com | P25: LH-N | Q25: 500 | S25: ARORA: Arkansas Regional Organ Recovery Agency | T25: Booth Space | U25: 545
A26: Smith Ford | B26: Silver | C26: 1000 | D26: 1000 | E26: BL | F26: 2.1.25 | I26: 7/31/25 GB | J26: 45967 | K26: 1000 | L26: Cate McConnell | N26: cate.mcconnell@smithford.com | P26: LH-O | S26: Arvest | T26: Booth Space | U26: 500 | V26: BL
A27: RE/MAX Elite: Karen Ferguson | B27: Silver | C27: 1000 | D27: 1000 | E27: LC | F27: 2.4.25 | I27: 7/31/25 GB | J27: 45895 | K27: 1000 | L27: Karen Ferguson | N27: karenferguson501@gmail.com | P27: (blank) | Q27: 10870 | S27: ASAP Personal Services | T27: Booth Space | U27: 570 | V27: JE-N
A28: First Security Bank | B28: Silver | C28: 1000 | D28: 1090 | E28: BL | F28: 3.19.25 | I28: 7/31/25 GB | J28: 45960 | K28: 1090 | L28: Stefanie Vann | N28: stefanie.vann@fsbank.com | P28: MM | Q28: 0 | S28: Attorney's Title Group | T28: Booth Space | U28: 530 | V28: LC-N
A29: Klaasmeyer | B29: Silver | C29: 1000 | D29: 1000 | E29: BL | F29: 4.10.25 | I29: 7/31/25 GB | L29: Jessica Press | N29: jessica@klaasmeyer.com | P29: TOTAL | Q29: 99570 | S29: Baptist Health Conway | T29: Title | U29: 7500 | V29: JG
A30: Attorney's Title Group | B30: Silver | C30: 1000 | D30: 1000 | E30: LC-N | F30: 7.8.25 | I30: 7/31/25 GB | J30: 45873 | K30: 1000 | L30: Whitley Compton-Hobbs | N30: wcompton-hobbs@TheWilsonLawFirm.com | S30: Baptist Health Urgent Care | T30: Premier Vendor | U30: 750 | V30: LH-N
A31: Southern Tee's | B31: Silver | C31: 1000 | D31: 1000 | E31: LC-N | F31: 7.8.25 | I31: 7/31/25 GB | J31: 45869 | K31: 1000 | L31: Sean Barber | N31: sotees@hotmail.com | S31: Bledsoe Chiropractic | T31: Premier Vendor | U31: 850 | V31: LC
A32: Ortho Arkansas | B32: Silver | C32: 1000 | D32: 1000 | E32: LC | F32: 7.8.25 | I32: 7/31/25 GB | J32: 45895 | K32: 1000 | L32: Traci Byrd | N32: Traci.Byrd@orthoarkansas.com | S32: Blue Barn Bakery | T32: TOC Food Vendor | U32: 0
A33: Arkansas Spine and Pain | B33: Silver | C33: 1000 | D33: 1000 | E33: JE-N | F33: 8.19.25 | I33: 8/26/25 GB | J33: 45951 | K33: 1000 | L33: Bradley Barber | N33: bradley@arkansasspineandpain.com | S33: Boston Mountain Rural Health | T33: Booth Space | U33: 500 | V33: JE-N
A34: The Max | B34: Silver | C34: 1000 | D34: 1000 | F34: 9.20.25 | G34: Wants booth 67. | J34: 45919 | K34: 1000 | L34: Pete Tanguay | N34: pete@rockpondpros.com | S34: Brick and Forge | T34: TOC Food Vendor | U34: 0
A35: Solid Rock | B35: Silver | C35: 1000 | D35: 0 | G35: In-kind | I35: 0 | S35: Bulgogi | T35: TOC Food Vendor | U35: 0
A36: Chris Crain Enterprises | B36: Taste of Conway | C36: 3500 | D36: 2000 | E36: BL | F36: 11.20.24 | G36: Confirm with NK/BB which Chris Crain Enterprises company/companies will be featured on event. | I36: 7/31/25 GB | J36: 45940 | K36: 2000 | L36: Brett Berry, Nita Kat Freeman | N36: brettberry@chriscraingroup.com; nitafreeman@chriscraingroup.com | S36: Business Ticket Purchases | T36: Tickets | U36: 725
A37: Molex | B37: Taste of Conway | C37: 3500 | D37: 3500 | E37: BL | F37: 3.28.25 | I37: 7/31/25 GB | J37: 45922 | K37: 3500 | L37: Cory Ensley | N37: cory.ensley@molex.com | S37: CARTI | T37: Gold | U37: 2000 | V37: LC
A38: Harvest Cannabis | B38: Networking Game | C38: 2500 | D38: 2500 | E38: LC | F38: 4.14.25 | G38: If they do not pay by September 1 OR confirm payment arrangements they will be removed as a sponsor for 2025. | I38: 7/31/25 GB | J38: 45880 | K38: 2500 | L38: Robbin | N38: robbin@harvestcannabisarkansas.com | S38: Central Baptist College | T38: Booth Space | U38: 670 | V38: LH
A39: Rogers Group | B39: Meal | C39: 2500 | D39: 2000 | E39: BL | F39: 1.3.25 | I39: 7/31/25 GB | J39: 45883 | K39: 2000 | L39: Mike Connelly | N39: mike.connelly@rogersgroupinc.com | S39: Century 21 Parker and Scroggins | T39: Booth Space | U39: 500 | V39: JE-N
A40: GARVER | B40: Meal | C40: 2500 | D40: 1350 | E40: JG | F40: 2.18.25 | I40: 7/31/25 GB | J40: 45891 | K40: 1350 | L40: Dustin Tackett | N40: DLTackett@GarverUSA.com | S40: Certapro | T40: Booth Space | U40: 565 | V40: LC-N
A41: Lane Housley Trucking | B41: Meal | C41: 2500 | D41: 2500 | E41: BL | F41: 2.23.25 | G41: Place booth next to Crafton Tull and Rogers Group | I41: 7/31/25 GB | J41: 45939 | K41: 2500 | L41: Lane Housley | N41: lane.housley@craftontull.com | S41: Chairman's Circle | T41: 1 Taste, 1 Breakfast OR Lunch, 1 session ticket | U41: 0
...

Sheet Catfish & Cold Ones
A1: CATFISH & COLD ONES | B1: 2025 | S1: CATFISH & COLD ONES | T1: 2024
A2: Total Sponsorship Amount Sold | B2: =SUM(D9:D71) -> 43925 | K2: OUTSTANDING | S2: Total Sponsorship Amount Sold | T2: =SUM(U9:U54) -> 39573
A3: Budget Goal | B3: 25000 | K3: =MIN(K72-B2) -> -775 | S3: Budget Goal | T3: 20000
A4: Remaining Balance | B4: =MIN(B2-B3) -> 18925 | K4: =K72/B2 -> 0.98235629 | S4: Remaining Balance | T4: =MIN(T2-T3) -> 19573
A5: Stretch Goal | B5: 45000 | S5: Stretch Goal | T5: 42000
A6: Remaining Balance | B6: =MIN(B2-B5) -> -1075 | S6: Remaining Balance | T6: =MIN(T2-T5) -> -2427
A8: SPONSOR NAME | B8: SPONSORSHIP | C8: COST | D8: PRICE PLEDGED | E8: SOLD BY | F8: DATE SOLD | G8: NOTES | H8: SPECIAL BILLING | I8: INVOICED | J8: DATE PAID | K8: PAID AMOUNT | L8: CONTACT | M8: PHONE | N8: EMAIL | P8: SOLD BY | Q8: PLEDGED | S8: SPONSOR NAME | T8: SPONSORSHIP | U8: PRICE PLEDGED | V8: SOLD BY
A9: ARcare | B9: Title | C9: 7500 | D9: 7500 | E9: LH | F9: 3.4.25 | G9: Award/check presentation of $1,500 to the ARcare Foundation. | J9: 4.29.25 | K9: 7500 | L9: Garrett Morgan, Emily Brenneman | N9: Garrett.Morgan@arcare.net; Emily.Brenneman@arcare.net | P9: BL | Q9: 13500 | S9: Andy's Frozen Custard | T9: Silver | U9: 0 | V9: LH
A10: Green Bay Packaging | B10: Presenting | C10: 5000 | D10: 5000 | E10: BL | F10: 12.3.24 | H10: YES | J10: 6.5.25 | K10: 5000 | L10: Brad Harville, Christy Prater | N10: bharville@gbp.com, cprater@gbp.com | P10: BL-N | Q10: 6000 | S10: ARcare | T10: Title | U10: 7500 | V10: LH
A11: Caldwell Toyota | B11: Presenting | C11: 5000 | D11: 4000 | E11: JG-N | F11: 12.20.24 | J11: 3.31.25 | K11: 4000 | L11: Jay Caldwell | N11: jay@caldwellcares.com | P11: BL-O | S11: Bank OZK | T11: Individual Ticket | U11: 105
A12: Ozark Mountain Construction | B12: Presenting | C12: 5000 | D12: 5000 | E12: BL-N | F12: 4.8.25 | G12: Include Erin Long (erin@citychurch.tv) on event communication. | H12: YES | J12: 5.12.25 | K12: 5000 | L12: Scott and Laura Pelley | N12: laurapelley@gmail.com; scott@ozarkmtnco.com | P12: CP | S12: Belinda Burrier | T12: Individual Ticket | U12: 70
B13: Presenting | C13: 5000 | P13: CP-N | S13: Black Belt Media | T13: Individual Ticket | U13: 55
A14: Malvern National Bank | B14: Fishing Derby | C14: 2500 | D14: 2500 | E14: LH | F14: 2.18.25 | J14: 4.7.25 | K14: 2500 | L14: Andy Harris, Alica Brown, Alexander Baney | N14: aharris@mnbbank.com; abrown@mnbbank.com; abaney@mnbbank.com | P14: CP-O | S14: Bledsoe Chiropractic | T14: Individual Ticket | U14: 175 | V14: LC-N
A15: Rock City Outfitters | B15: T-shirt | C15: 1500 | D15: 1000 | E15: LC | F15: 2.24.25 | J15: 4.30.25 | K15: 1000 | L15: Ryan Ritchie | N15: ryan@rockcityoutfitters.com | P15: JE | Q15: 610 | S15: Caldwell Toyota | T15: Presenting | U15: 0 | V15: JG
A16: Conway Regional | B16: Gold | C16: 2500 | D16: 2500 | E16: BL | F16: 12.30.24 | J16: 4.9.25 | K16: 2500 | L16: Rebekah Fincher | N16: rfincher@conwayregional.org | P16: JE-N | Q16: 260 | S16: Caldwell Toyota | T16: Individual Ticket | U16: 70
A17: Turbare | B17: Gold | C17: 2500 | D17: 2500 | E17: BL | F17: 1.3.25 | G17: 10 tickets | H17: YES | J17: 7.7.25 | K17: 2500 | L17: Laura Martin, Andria White | N17: ceo@turbare.org; awhite@turbare.org | P17: JE-O | S17: Car-son Construction | T17: Gold | U17: 2500 | V17: BL-N
A18: Car-Son Construction | B18: Gold | C18: 2500 | D18: 2500 | E18: BL | F18: 2.28.25 | G18: 4 tickets to the event. | H18: YES | J18: 4.10.25 | K18: 2500 | L18: Brad Fason, Brian Fason | N18: bfason@car-son.com; bradfason@car-son.com | P18: JG | S18: Cintas | T18: Silver | U18: 1350 | V18: LH
B19: Gold | C19: 2500 | P19: JG-N | Q19: 4000 | S19: City of Conway | T19: Individual Ticket | U19: 0
B20: Gold | C20: 2500 | P20: JG-O | S20: Claire Carter Smithson, Homeward Realty | T20: Individual Ticket | U20: 105 | V20: LC-N
B21: Gold | C21: 2500 | P21: LC | Q21: 2930 | S21: Conway Regional | T21: Gold | U21: 2500 | V21: BL-N
A22: Crafton Tull | B22: Silver | C22: 1000 | D22: 1000 | E22: BL | F22: 1.10.25 | H22: YES | J22: 45887 | K22: 1410 | L22: Lane Housley | N22: lane.housley@craftontull.com | P22: LC-N | Q22: 2475 | S22: Crafton Tull | T22: Silver | U22: 1000 | V22: BL
A23: WACO Title | B23: Silver | C23: 1000 | D23: 1000 | E23: LC-N | F23: 2.7.25 | G23: 8 tickets | J23: 45880 | K23: 1000 | L23: Ryke Dismuke, Brooklyn Burnett | N23: idismuke@wacotitle.com: bburnett1@wacotitle.com | P23: LC-O | S23: Custom Glass | T23: Individual Ticket | U23: 815 | V23: JE-N
A24: The Pest Detective | B24: Silver | C24: 1000 | D24: 1000 | E24: LC-N | G24: provide ability for sponsor to have display area | J24: 45925 | K24: 1000 | L24: Westly Sullins | N24: westhepestdetective@gmail.com | P24: LH | Q24: 12015 | S24: Diamond State Restoration | T24: Silver | U24: 1000 | V24: LC
A25: Cintas | B25: Silver | C25: 1000 | D25: 1350 | E25: LH | F25: 2.25.24 | G25: Plus 10 additional tickets | J25: 3.21.25 | K25: 1350 | L25: Mathew Hoppis | N25: HoppisM@cintas.com | P25: LH-N | S25: Empower Healthcare Solutions | T25: Gold | U25: 2500 | V25: LH
A26: Cousins' | B26: Silver | C26: 1000 | D26: 0 | E26: LH | F26: 2.26.25 | G26: in-kind for hauling event materials | K26: 0 | L26: Adam Robertson, Tara Robertson | N26: adam@cousinsfurniture.com; tara@cousinsfurniture.com | P26: LH-O | S26: Farris Agency | T26: Individual Ticket | U26: 180 | V26: JE-N
A27: Snap-on | B27: Silver | C27: 1000 | D27: 1000 | E27: BL-N | F27: 3.10.25 | H27: YES | J27: 3.28.25 | K27: 1000 | L27: Scott Champlin, Lynne Sponer | N27: scott.l.champlin@snapon.com; lynne.sponer@snapon.com | P27: (blank) | Q27: 2035 | S27: Gate Sales | T27: Individual Ticket | U27: 368
A28: Lost Forty | B28: Silver | C28: 1000 | D28: 0 | P28: TOTAL | Q28: 43825 | S28: Green Bay Packaging | T28: Presenting | U28: 5000 | V28: BL
A29: Point Remoe Brewing Co. | B29: Silver | C29: 1000 | D29: 0 | S29: Hampton Inn and Suites | T29: Individual Ticket | U29: 70 | V29: JE-N
A30: The Rogue Roundabout | B30: Silver | C30: 1000 | D30: 0 | S30: Haynes Ace Hardware | T30: Individual Ticket | U30: 35 | V30: JE-N
A31: Westport Dental | B31: Silver | C31: 1000 | D31: 1000 | E31: LC | F31: 3.26.25 | J31: 4.1.25 | K31: 1000 | L31: Cyndi Winter | N31: cwinter.westport@conwaycorp.net | S31: Home2/Hilton Garden Inn | T31: Individual Ticket | U31: 140 | V31: JE-N
A32: Highpoint Park Apartments (Trinity Development) | B32: Individual Ticket | C32: 35 | D32: 455 | E32: LH | F32: 3.6.25 | J32: 3.6.25 | K32: 455 | L32: Courtnie Pledger | N32: cpledger@trinitydevelopmentinc.com | S32: Malvern National Bank | T32: Fishing Derby | U32: 2500 | V32: LH
A33: Ott Insurance | B33: Individual Ticket | C33: 35 | D33: 175 | E33: LC-N | F33: 2.7.25 | G33: 5 tickets | J33: 3.10.25 | K33: 175 | L33: Michelle Mallett | N33: michellemallett@ottinsurance.com | S33: Megan Stewart | T33: Individual Ticket | U33: 110 | V33: LC-N
A34: SMC Conway, A Division of GBP | B34: Individual Ticket | C34: 35 | D34: 210 | E34: LH | F34: 3.14.25 | H34: YES | J34: 45877 | K34: 210 | L34: Jimmy Toal, Sonya Griffis | N34: jimmy.toal@smcpackaging.com; sonya.griffis@smcpackaging.com | S34: Online Sales | T34: Individual Ticket | U34: 1210
A35: Morgan Drayton | B35: Individual Ticket | C35: 35 | D35: 125 | G35: 4 tickets | J35: 4.17.25 | K35: 125 | S35: Ott Insurance | T35: Individual Ticket | U35: 140 | V35: LC
A36: Tommy's Car Wash | B36: Individual Ticket | C36: 35 | D36: 0 | E36: JE | F36: 3.21.25 | G36: 3 tickets | L36: Kason | S36: PCSI | T36: Individual Ticket | U36: 140 | V36: LC-N
A37: Window Depot | B37: Individual Ticket | C37: 35 | D37: 70 | E37: LC | F37: 3.24.25 | J37: 3.24.25 | K37: 70 | L37: Zack Venable, Karen | N37: zack@windowdepotar.com; office.windowdepotar@gmail.com | S37: Power Spine and Sport | T37: Individual Ticket | U37: 60 | V37: JE-N
A38: P.I. Roofing and Construction | B38: Individual Ticket | C38: 35 | D38: 70 | F38: 3.24.25 | J38: 3.24.25 | K38: 70 | S38: Rock City Outfitters | T38: T-Shirt | U38: 1000 | V38: LC
A39: Major A Yard Games | B39: Individual Ticket | C39: 35 | D39: 105 | E39: JE-N | F39: 3.31.25 | G39: 3 tickets | J39: 4.22.25 | K39: 105 | L39: Lyn Alexander | N39: alexanderlynbusiness@gmail.com | S39: Scott Coffey | T39: Individual Ticket | U39: 70
A40: Turbare | B40: Individual Ticket | C40: 35 | D40: 420 | F40: 3.31.25 | J40: 3.31.25 | K40: 420 | S40: Simmons Bank | T40: Individual Ticket | U40: 70
A41: Adena White | B41: Individual Ticket | C41: 35 | D41: 55 | F41: 3.31.25 | J41: 3.31.25 | K41: 55 | S41: Steve Wade | T41: Individual Ticket | U41: 70
...

Sheet CDC Membership
A1: CDC MEMBERSHIP | B1: 2025
A2: Total Sponsorship Amount Sold | B2: =SUM(D9:D117) -> 171850 | K2: OUTSTANDING
A3: Budget Goal | B3: 173000 | K3: =MIN(K119-B2) -> -3350
A4: Remaining Balance | B4: =MIN(B2-B3) -> -1150 | K4: =K119/B2 -> 0.98050626
A5: Stretch Goal | B5: 173000
A6: Remaining Balance | B6: =MIN(B2-B5) -> -1150
A8: SPONSOR NAME | B8: MEMBERSHIP LEVEL | C8: COST | D8: PRICE PLEDGED | E8: SOLD BY | F8: DATE SOLD | G8: NOTES | H8: SPECIAL BILLING | I8: INVOICED | J8: DATE PAID | K8: PAID AMOUNT | L8: CONTACT | M8: PHONE | N8: EMAIL | P8: SOLD BY | Q8: PLEDGED
A9: Acxiom | B9: Three Voting Members | C9: 3000 | D9: 3000 | E9: BL-N | F9: 1.8.25 | J9: 3.13.25 | K9: 3000 | L9: Crystal Floyd, Alison Cowles | N9: Crystal.Floyd@acxiom.com; Alison.Cowles@acxiom.com | P9: BL | Q9: 21500
A10: Alliance Investment Group, LLC | B10: One Voting Member | C10: 1500 | P10: BL-N | Q10: 37350
A11: American Safeguard Insurance | B11: One Voting Member | C11: 1500 | D11: 1500 | E11: LH-N | F11: 12.23.24 | H11: YES | J11: 1.17.25 | K11: 1500 | L11: Jeremy Davis, Jason Smith, | N11: jdavis@asiagents.com; jsmith@asiagents.com; | P11: BL-O
A12: Arvest Bank | B12: Three Voting Members | C12: 3000 | D12: 3000 | E12: BL-N | F12: 2.4.24 | H12: YES | J12: 3.31.25 | K12: 3000 | L12: Brooks Davis, Maret Cahill Wicks | N12: mcahillwicks@arvest.com; bdavis3@arvest.com | P12: CP | Q12: 6000
A13: AT&T | B13: One Voting Member | C13: 1500 | D13: 1500 | E13: JG-N | F13: 5.9.25 | J13: 5.9.25 | K13: 1500 | P13: CP-N | Q13: 7500
A14: Attorney's Title Group | B14: One Voting Member | C14: 1500 | D14: 1500 | E14: LC | F14: 4.7.25 | J14: 4.7.25 | K14: 1500 | P14: CP-O
A15: B&A Property Maintenance | B15: One Voting Member | C15: 1500 | D15: 1500 | E15: JG-N | F15: 4.25.25 | J15: 45919 | K15: 1500 | L15: Ryan Johnson | N15: rjohnson@bandapm.com | P15: JE
A16: Baptist Health Medical Center, Conway | B16: Three Voting Members | C16: 3000 | D16: 1500 | E16: JG | F16: 1.13.25 | J16: 7.28.25 | K16: 1500 | L16: April Bennett | P16: JE-N | Q16: 1500
A17: Cadence Bank | B17: One Voting Member | C17: 1500 | D17: 1500 | E17: LH-N | F17: 2.28.25 | J17: 6.3.25 | K17: 1500 | L17: Tom Nelson | N17: tom.nelson@cadencebank.com | P17: JE-O
A18: Car-Son Construction | B18: One Voting Member | C18: 1500 | D18: 1350 | E18: BL-N | F18: 2.28.25 | H18: YES | J18: 5.16.25 | K18: 1350 | L18: Brad Fason, Brian Fason | N18: bfason@car-son.com; bradfason@car-son.com | P18: JG | Q18: 7500
A19: Carty, Harding & Hearn, Inc. | B19: One Voting Member | C19: 1500 | D19: 1500 | J19: March | K19: 1500 | P19: JG-N | Q19: 12000
A20: Catalyst Financial | B20: One Voting Member | C20: 1500 | D20: 1500 | E20: LH-N | F20: 2.24.25 | J20: 6.3.25 | K20: 1500 | L20: Drew Gainor | N20: dgainor@financialguide.com | P20: JG-O
A21: Centennial Bank | B21: Three Voting Members | C21: 3000 | D21: 3000 | J21: 45923 | K21: 3000 | P21: LC | Q21: 1500
A22: Central Baptist College | B22: One Voting Member | C22: 1500 | D22: 1500 | E22: LH-N | F22: 1.28.25 | J22: 5.27.25 | K22: 1500 | L22: Terry Kimbrow/Jeremy Langley | N22: tkimbrow@cbc.edu; jlangley@cbc.edu | P22: LC-N | Q22: 7500
A23: Chris Crain Enterprises | B23: One Voting Member | C23: 1500 | D23: 1500 | E23: BL-N | F23: 11.20.24 | J23: 45943 | K23: 1500 | L23: Brett Berry | N23: brettberry@chriscraingroup.com | P23: LC-O
A24: Cintas | B24: One Voting Member | C24: 1500 | D24: 1500 | E24: LH-N | F24: 2.25.24 | J24: 3.21.25 | K24: 1500 | L24: Mathew Hoppis | N24: HoppisM@cintas.com | P24: LH | Q24: 10500
B25: One Voting Member | C25: 1500 | P25: LH-N | Q25: 31500
A26: Clayton Conway | B26: Three Voting Members | C26: 3000 | D26: 3000 | E26: CP-N | G26: All communications – Jamar Murchison – jamar.murchison@claytonhomes.com All communications – Stephanie Amerson – stephanie.amerson@claytonhomes.com Billing – Jake Turpin – jake.turpin@claytonhomes.com | J26: 4.15.25 | K26: 3000 | L26: Jake Turpin | N26: jake.turpin@claytonhomes.com | P26: LH-O | Q26: 5000
A27: Colliers | B27: One Voting Member | C27: 1500 | D27: 1500 | E27: BL | J27: 3.14.25 | K27: 1500 | P27: (blank) | Q27: 13500
A28: Conductor | B28: One Voting Member | C28: 1500 | D28: 1500 | E28: LH-N | F28: 1.13.25 | J28: 2.25.25 | K28: 1500 | L28: Grace Rains | N28: grace@arconductor.org | P28: TOTAL | Q28: 162850
B29: One Voting Member | C29: 1500
A30: Conway Behavioral Health - Acadia Health Care | B30: One Voting Member | C30: 1500 | D30: 1500 | E30: LH-N | F30: 3.10.25 | J30: 4.2.25 | K30: 1500 | L30: Valencia Anderson | N30: Valencia.Anderson@conwaybh.com
A31: Conway Corporation | B31: Five Voting Members | C31: 100000 | D31: 0 | G31: per agreement | K31: 0 | L31: Bret Carroll
A32: Conway Regional | B32: Three Voting Members | C32: 3000 | D32: 3000 | E32: BL | F32: 12.30.24 | J32: 3.14.25 | K32: 3000 | L32: Rebekah Fincher, Matt Troup | N32: rfincher@conwayregional.org; matt.troup@conwayregional.org
A33: Conway Wealth Management | B33: One Voting Member | C33: 1500 | D33: 1500 | E33: BL | K33: 1500
A34: Corco Construction | B34: One Voting Member | C34: 1500 | D34: 1500 | E34: BL-N | F34: 3.18.25 | J34: 45831 | K34: 1500 | L34: Justin Bennett, Jon Virden | N34: jvirden@corcoconstruction.com; jbennett@corcoconstruction.com
A35: Covington Companies | B35: One Voting Member | C35: 1500 | D35: 1500 | E35: BL-N | F35: 3.13.25 | J35: 3.13.25 | K35: 1500
A36: Crafton Tull | B36: One Voting Member | C36: 1500 | D36: 1500 | E36: BL-N | F36: 1.10.25 | H36: YES | J36: 45944 | K36: 1500 | L36: Lane Housley | N36: lane.housley@craftontull.com
